Workbook

Sheet main
A1: Full author list | B1: First Author(s) & Year | C1: Article Title | D1: Application/Technology | E1: Tech Used | F1: Drone type | G1: is_ag | H1: DOI Link | I1: Abstract | J1: Country(ies) | K1: Tools | L1: SEA_status | M1: Section_relevance | N1: In_manuscript
A2: {=XLOOKUP(C2, 'raw data'!A:A, 'raw data'!D:D, "Not found")} | B2: Abramowitz et al. (2023) | C2: Differentiating oil palm plantations from natural forest to improve land cover mapping in Ghana | D2: Oil palm plantation mapping | E2: Satellite | G2: 1 | H2: 10.1016/j.rsase.2023.100968 | I2: {=XLOOKUP(C2, 'raw data'!A:A, 'raw data'!C:C, "Not found")} | J2: Ghana | K2: {=XLOOKUP(C2, 'title&tool'!A:A, 'title&tool'!B:B, "Not found")} | L2: Non-SEA → review for removal | M2: 2.1 Remote Sensing | N2: Yes
A3: {=XLOOKUP(C3, 'raw data'!A:A, 'raw data'!D:D, "Not found")} | B3: Afuye et al. (2024) | C3: Global trend assessment of land use and land cover changes: A systematic approach to future research development and planning | D3: LULC change research trend assessment | E3: NA (Systematic Review) | H3: 10.1016/j.jksus.2024.103262 | I3: {=XLOOKUP(C3, 'raw data'!A:A, 'raw data'!C:C, "Not found")} | J3: Global | K3: {=XLOOKUP(C3, 'title&tool'!A:A, 'title&tool'!B:B, "Not found")} | L3: Background (keep) | M3: Intro/Background | N3: No
A4: {=XLOOKUP(C4, 'raw data'!A:A, 'raw data'!D:D, "Not found")} | B4: Agarwal & Lambin (2024) | C4: Interventions to control forest loss in a swidden cultivation landscape in Nan Province, Thailand | D4: Forest loss in swidden cultivation landscape | E4: Satellite | G4: 0 | H4: 10.1007/s10113-024-02286-5 | I4: {=XLOOKUP(C4, 'raw data'!A:A, 'raw data'!C:C, "Not found")} | J4: Thailand | K4: {=XLOOKUP(C4, 'title&tool'!A:A, 'title&tool'!B:B, "Not found")} | L4: SEA | M4: 2.1 Remote Sensing | N4: No
A5: {=XLOOKUP(C5, 'raw data'!A:A, 'raw data'!D:D, "Not found")} | B5: Agduma & Cao (2023) | C5: Species richness, extent and potential threats to mangroves of Sarangani Bay Protected Seascape, Philippines | D5: Mangrove species richness and threats assessment | E5: NA (Spatial analysis) | G5: 0 | H5: 10.3897/BDJ.11.e100050 | I5: {=XLOOKUP(C5, 'raw data'!A:A, 'raw data'!C:C, "Not found")} | J5: Philippines | K5: {=XLOOKUP(C5, 'title&tool'!A:A, 'title&tool'!B:B, "Not found")} | L5: SEA | M5: General | N5: No
A6: {=XLOOKUP(C6, 'raw data'!A:A, 'raw data'!D:D, "Not found")} | B6: Ahmad et al. (2025) | C6: Land use and land cover dynamics in the Irrawaddy Delta: Remote sensing analysis and projections for the future | D6: LULC dynamics and future projections | E6: Satellite | G6: 0 | H6: 10.1016/j.rsase.2025.101607 | I6: {=XLOOKUP(C6, 'raw data'!A:A, 'raw data'!C:C, "Not found")} | J6: Myanmar | K6: {=XLOOKUP(C6, 'title&tool'!A:A, 'title&tool'!B:B, "Not found")} | L6: SEA | M6: 2.1 Remote Sensing | N6: Yes
A7: {=XLOOKUP(C7, 'raw data'!A:A, 'raw data'!D:D, "Not found")} | B7: Ahmad et al. (2024) | C7: Role of Smart Agriculture Techniques in Food Security: A Systematic Review | D7: Smart agriculture techniques review | E7: Satellite, Drone, IoT, Sensors | F7: others | G7: 1 | H7: 10.1111/jac.12758 | I7: {=XLOOKUP(C7, 'raw data'!A:A, 'raw data'!C:C, "Not found")} | J7: Global (Multiple) | K7: {=XLOOKUP(C7, 'title&tool'!A:A, 'title&tool'!B:B, "Not found")} | L7: Background (keep) | M7: 2.1 Remote Sensing; 2.2 IoT; Intro/Background | N7: Yes
A8: {=XLOOKUP(C8, 'raw data'!A:A, 'raw data'!D:D, "Not found")} | B8: Ahmadi et al. (2023) | C8: CONVOLUTIONAL SVM NETWORKS FOR DETECTION OF GANODERMA BONINENSE AT EARLY STAGE IN OIL PALM USING UAV AND MULTISPECTRAL PLEIADES IMAGES | D8: Ganoderma disease detection in oil palm | E8: Drone, Satellite | F8: ms | G8: 1 | H8: 10.5194/isprs-annals-X-4-W1-2022-25-2023 | I8: {=XLOOKUP(C8, 'raw data'!A:A, 'raw data'!C:C, "Not found")} | J8: Malaysia | K8: {=XLOOKUP(C8, 'title&tool'!A:A, 'title&tool'!B:B, "Not found")} | L8: SEA | M8: 2.1 Remote Sensing, 2.4 AI Models | N8: Yes
A9: {=XLOOKUP(C9, 'raw data'!A:A, 'raw data'!D:D, "Not found")} | B9: Albertazzi & Bini (2025) | C9: Tropical deforestation and the state: Settlement schemes in the Mau forest of Kenya (1991-2001) | D9: Deforestation and settlement scheme analysis | E9: Satellite | G9: 0 | H9: 10.1016/j.wdp.2025.100675 | I9: {=XLOOKUP(C9, 'raw data'!A:A, 'raw data'!C:C, "Not found")} | J9: Kenya | K9: {=XLOOKUP(C9, 'title&tool'!A:A, 'title&tool'!B:B, "Not found")} | L9: Non-SEA → review for removal | M9: 2.1 Remote Sensing | N9: No
A10: {=XLOOKUP(C10, 'raw data'!A:A, 'raw data'!D:D, "Not found")} | B10: Alaboz et al. (2023) | C10: Soil quality assessment based on machine learning approach for cultivated lands in semi-humid environmental condition part of Black Sea region | D10: Soil quality assessment | E10: NA (GIS) | G10: 0 | H10: 10.1080/03650340.2023.2248002 | I10: {=XLOOKUP(C10, 'raw data'!A:A, 'raw data'!C:C, "Not found")} | J10: Turkey | K10: {=XLOOKUP(C10, 'title&tool'!A:A, 'title&tool'!B:B, "Not found")} | L10: Non-SEA → review for removal | M10: General | N10: No
A11: {=XLOOKUP(C11, 'raw data'!A:A, 'raw data'!D:D, "Not found")} | B11: Alejo et al. (2024) | C11: Spacio-Temporal Estimation of Soil Erosion by Revised Universal Soil Loss Equation Model in Pantabangan-Carranglan Watershed, Philippines | D11: Soil erosion estimation | E11: Satellite, GIS | G11: 0 | H11: 10.12911/22998993/191029 | I11: {=XLOOKUP(C11, 'raw data'!A:A, 'raw data'!C:C, "Not found")} | J11: Philippines | K11: {=XLOOKUP(C11, 'title&tool'!A:A, 'title&tool'!B:B, "Not found")} | L11: SEA | M11: 2.1 Remote Sensing | N11: Yes
A12: {=XLOOKUP(C12, 'raw data'!A:A, 'raw data'!D:D, "Not found")} | B12: Alonzo et al. (2023) | C12: Drought Risk Assessment and Monitoring of Ilocos Norte Province in the Philippines Using Satellite Remote Sensing and Meteorological Data | D12: Drought risk assessment & monitoring | E12: Satellite | G12: 1 | H12: 10.3390/agriengineering5020045 | I12: {=XLOOKUP(C12, 'raw data'!A:A, 'raw data'!C:C, "Not found")} | J12: Philippines | K12: {=XLOOKUP(C12, 'title&tool'!A:A, 'title&tool'!B:B, "Not found")} | L12: SEA | M12: 2.1 Remote Sensing | N12: No
A13: {=XLOOKUP(C13, 'raw data'!A:A, 'raw data'!D:D, "Not found")} | B13: Amongo et al. (2023) | C13: A GIS-based land suitability model for agricultural tractors in CALABARZON Region, Philippines | D13: Land suitability for agricultural tractors | E13: NA (GIS) | G13: 1 | H13: 10.1038/s41598-023-45071-w | I13: {=XLOOKUP(C13, 'raw data'!A:A, 'raw data'!C:C, "Not found")} | J13: Philippines | K13: {=XLOOKUP(C13, 'title&tool'!A:A, 'title&tool'!B:B, "Not found")} | L13: SEA | M13: 2.3 Robotics | N13: No
A14: {=XLOOKUP(C14, 'raw data'!A:A, 'raw data'!D:D, "Not found")} | B14: Ampha & Wongbumru (2025) | C14: The Analysis of Agricultural Areas to Support Urban Development based on Green Economy in Roi Et Province, Thailand | D14: Agricultural area analysis for urban development | E14: NA (GIS) | G14: 1 | H14: 10.14246/irspsd.13.2_90 | I14: {=XLOOKUP(C14, 'raw data'!A:A, 'raw data'!C:C, "Not found")} | J14: Thailand | K14: {=XLOOKUP(C14, 'title&tool'!A:A, 'title&tool'!B:B, "Not found")} | L14: SEA | M14: General | N14: No
A15: {=XLOOKUP(C15, 'raw data'!A:A, 'raw data'!D:D, "Not found")} | B15: Anh & Hanh (2025) | C15: Toward Sustainable Agriculture: An Evaluation of Mechanization Practices in Small-Scale Paddy Farming in the Mekong River Delta, Vietnam | D15: Mechanization in small-scale paddy farming | E15: NA (Survey data) | G15: 1 | H15: 10.37801/ajad2025.22.1.2 | I15: {=XLOOKUP(C15, 'raw data'!A:A, 'raw data'!C:C, "Not found")} | J15: Vietnam | K15: {=XLOOKUP(C15, 'title&tool'!A:A, 'title&tool'!B:B, "Not found")} | L15: SEA | M15: 2.3 Robotics | N15: No
A16: {=XLOOKUP(C16, 'raw data'!A:A, 'raw data'!D:D, "Not found")} | B16: Ansari et al. (2024) | C16: Forest cover change and its carbon dynamic of the karst area in Bulusaraung, South Sulawesi, Indonesia | D16: Forest cover change & carbon dynamics in karst areas | E16: Satellite | G16: 0 | H16: 10.1080/21580103.2024.2343344 | I16: {=XLOOKUP(C16, 'raw data'!A:A, 'raw data'!C:C, "Not found")} | J16: Indonesia | K16: {=XLOOKUP(C16, 'title&tool'!A:A, 'title&tool'!B:B, "Not found")} | L16: SEA | M16: 2.1 Remote Sensing | N16: No
A17: {=XLOOKUP(C17, 'raw data'!A:A, 'raw data'!D:D, "Not found")} | B17: Ariska et al. (2025) | C17: Groundwater Potential Mapping (GWPM) using Analytical Hierarchy Process (AHP) in Bengkulu City, Indonesia | D17: Groundwater potential mapping | E17: NA (GIS, AHP) | G17: 0 | H17: 10.17794/rgn.2025.3.1 | I17: {=XLOOKUP(C17, 'raw data'!A:A, 'raw data'!C:C, "Not found")} | J17: Indonesia | K17: {=XLOOKUP(C17, 'title&tool'!A:A, 'title&tool'!B:B, "Not found")} | L17: SEA | M17: General | N17: No
A18: {=XLOOKUP(C18, 'raw data'!A:A, 'raw data'!D:D, "Not found")} | B18: Arumugam et al. (2024) | C18: Land use changes and climate parameters assessments in a tropical highland region of Cameron Highlands, Malaysia | D18: LULC & climate parameter assessments | E18: Satellite | G18: 0 | H18: 10.2166/wcc.2024.552 | I18: {=XLOOKUP(C18, 'raw data'!A:A, 'raw data'!C:C, "Not found")} | J18: Malaysia | K18: {=XLOOKUP(C18, 'title&tool'!A:A, 'title&tool'!B:B, "Not found")} | L18: SEA | M18: 2.1 Remote Sensing | N18: No
A19: {=XLOOKUP(C19, 'raw data'!A:A, 'raw data'!D:D, "Not found")} | B19: Asawapaisankul et al. (2025) | C19: Correlation of yield and vegetation indices from unmanned aerial vehicle multispectral imagery in Thailand rice production systems | D19: Rice yield & vegetation indices correlation | E19: Drone | F19: ms | G19: 1 | H19: 10.1002/agg2.70107 | I19: {=XLOOKUP(C19, 'raw data'!A:A, 'raw data'!C:C, "Not found")} | J19: Thailand | K19: {=XLOOKUP(C19, 'title&tool'!A:A, 'title&tool'!B:B, "Not found")} | L19: SEA | M19: 2.1 Remote Sensing | N19: Yes
A20: {=XLOOKUP(C20, 'raw data'!A:A, 'raw data'!D:D, "Not found")} | B20: Asmara et al. (2024) | C20: Spatial identification of lost-and-found carbon hotspots at Javanese rice systems, Indonesia | D20: Carbon stock potential in rice systems | E20: Satellite | G20: 1 | H20: 10.1016/j.agsy.2023.103834 | I20: {=XLOOKUP(C20, 'raw data'!A:A, 'raw data'!C:C, "Not found")} | J20: Indonesia | K20: {=XLOOKUP(C20, 'title&tool'!A:A, 'title&tool'!B:B, "Not found")} | L20: SEA | M20: 2.1 Remote Sensing | N20: Yes
A21: {=XLOOKUP(C21, 'raw data'!A:A, 'raw data'!D:D, "Not found")} | B21: Asyiqin & Ong (2025) | C21: Adapting forest plantations to climate change: strategies, challenges, and opportunities in Malaysia | D21: Forest plantation adaptation to climate change | E21: NA (Review, Remote Sensing) | H21: 10.1007/s11056-025-10105-w | I21: {=XLOOKUP(C21, 'raw data'!A:A, 'raw data'!C:C, "Not found")} | J21: Malaysia | K21: {=XLOOKUP(C21, 'title&tool'!A:A, 'title&tool'!B:B, "Not found")} | L21: SEA | M21: 2.1 Remote Sensing; Intro/Background | N21: No
A22: {=XLOOKUP(C22, 'raw data'!A:A, 'raw data'!D:D, "Not found")} | B22: Azizan et al. (2023) | C22: Rubber leaf fall phenomenon linked to increased temperature | D22: Rubber leaf fall phenology & temperature linkage | E22: Satellite | G22: 1 | H22: 10.1016/j.agee.2023.108531 | I22: {=XLOOKUP(C22, 'raw data'!A:A, 'raw data'!C:C, "Not found")} | J22: Indonesia, Sri Lanka, Malaysia, Cambodia | K22: {=XLOOKUP(C22, 'title&tool'!A:A, 'title&tool'!B:B, "Not found")} | L22: SEA | M22: 2.1 Remote Sensing | N22: No
A23: {=XLOOKUP(C23, 'raw data'!A:A, 'raw data'!D:D, "Not found")} | B23: Baharim et al. (2024) | C23: Modelling water use efficiency (WUE) for estimating the severity of Ganoderma boninense-derived basal stem rot disease in oil palm | D23: Oil palm disease severity estimation | E23: Drone, Sensors (Hyperspectral) | F23: hs | G23: 1 | H23: 10.1007/s42161-024-01770-5 | I23: {=XLOOKUP(C23, 'raw data'!A:A, 'raw data'!C:C, "Not found")} | J23: Malaysia, Indonesia | K23: {=XLOOKUP(C23, 'title&tool'!A:A, 'title&tool'!B:B, "Not found")} | L23: SEA | M23: 2.1 Remote Sensing; 2.2 IoT | N23: Yes
A24: {=XLOOKUP(C24, 'raw data'!A:A, 'raw data'!D:D, "Not found")} | B24: Baite et al. (2024) | C24: Agricultural land suitability analysis in Manipur, India using GIS and AHP | D24: Agricultural land suitability analysis | E24: Satellite | G24: 1 | H24: 10.14712/23361980.2024.6 | I24: {=XLOOKUP(C24, 'raw data'!A:A, 'raw data'!C:C, "Not found")} | J24: India | K24: {=XLOOKUP(C24, 'title&tool'!A:A, 'title&tool'!B:B, "Not found")} | L24: Non-SEA → review for removal | M24: 2.1 Remote Sensing | N24: No
A25: {=XLOOKUP(C25, 'raw data'!A:A, 'raw data'!D:D, "Not found")} | B25: Baldovino & Laurel (2024) | C25: Design and Development of a Tri-copter/Fixed-wing VTOL Drone for Post-Disaster Applications | D25: VTOL drone design for post-disaster use | E25: Drone | G25: 0 | H25: 10.1109/ICOM61675.2024.10652407 | I25: {=XLOOKUP(C25, 'raw data'!A:A, 'raw data'!C:C, "Not found")} | J25: Philippines | K25: {=XLOOKUP(C25, 'title&tool'!A:A, 'title&tool'!B:B, "Not found")} | L25: SEA | M25: 2.1 Remote Sensing | N25: Yes
A26: {=XLOOKUP(C26, 'raw data'!A:A, 'raw data'!D:D, "Not found")} | B26: Banu et al. (2024) | C26: Land suitability analysis for turmeric crop for humid tropical Kerala, India, under current and future climate scenarios using advanced geospatial techniques | D26: Turmeric crop suitability analysis | E26: NA (Geospatial techniques) | G26: 1 | H26: 10.1002/jsfa.13299 | I26: {=XLOOKUP(C26, 'raw data'!A:A, 'raw data'!C:C, "Not found")} | J26: India | K26: {=XLOOKUP(C26, 'title&tool'!A:A, 'title&tool'!B:B, "Not found")} | L26: Non-SEA → review for removal | M26: General | N26: No
A27: {=XLOOKUP(C27, 'raw data'!A:A, 'raw data'!D:D, "Not found")} | B27: Barbieri et al. (2025) | C27: Rice area-yield estimation based on the synergistic use of remote sensing time-series and crop growth modeling in Nigeria | D27: Rice area-yield estimation | E27: Satellite | G27: 1 | H27: 10.1016/j.atech.2025.101024 | I27: {=XLOOKUP(C27, 'raw data'!A:A, 'raw data'!C:C, "Not found")} | J27: Nigeria | K27: {=XLOOKUP(C27, 'title&tool'!A:A, 'title&tool'!B:B, "Not found")} | L27: Non-SEA → review for removal | M27: 2.1 Remote Sensing | N27: No
A28: {=XLOOKUP(C28, 'raw data'!A:A, 'raw data'!D:D, "Not found")} | B28: Basyuni et al. (2025) | C28: Reduction of mangrove carbon stock ecosystems due to illegal logging using a combination of unmanned aerial vehicle imagery and field surveys | D28: Mangrove carbon stock assessment & illegal logging | E28: Drone, Satellite | G28: 0 | H28: 10.22034/gjesm.2025.01.14 | I28: {=XLOOKUP(C28, 'raw data'!A:A, 'raw data'!C:C, "Not found")} | J28: Indonesia | K28: {=XLOOKUP(C28, 'title&tool'!A:A, 'title&tool'!B:B, "Not found")} | L28: SEA | M28: 2.1 Remote Sensing | N28: No
A29: {=XLOOKUP(C29, 'raw data'!A:A, 'raw data'!D:D, "Not found")} | B29: Bate & Dagamac (2025) | C29: Wallow land suitability assessment using GIS-based multicriteria decision-making framework | D29: Wallow land suitability assessment for tamaraw | E29: NA (GIS) | G29: 0 | H29: 10.1007/s10661-025-14111-5 | I29: {=XLOOKUP(C29, 'raw data'!A:A, 'raw data'!C:C, "Not found")} | J29: Philippines | K29: {=XLOOKUP(C29, 'title&tool'!A:A, 'title&tool'!B:B, "Not found")} | L29: SEA | M29: General | N29: No
A30: {=XLOOKUP(C30, 'raw data'!A:A, 'raw data'!D:D, "Not found")} | B30: Bautista et al. (2024) | C30: Development and Implementation of Drone Attachment Tank Sprayer (DATS) | D30: Drone sprayer development | E30: Drone | F30: others | G30: 1 | H30: 10.1109/ICMRE60776.2024.10532154 | I30: {=XLOOKUP(C30, 'raw data'!A:A, 'raw data'!C:C, "Not found")} | J30: Philippines | K30: {=XLOOKUP(C30, 'title&tool'!A:A, 'title&tool'!B:B, "Not found")} | L30: SEA | M30: 2.1 Remote Sensing; 2.3 Robotics | N30: No
A31: {=XLOOKUP(C31, 'raw data'!A:A, 'raw data'!D:D, "Not found")} | B31: Bayrakli et al. (2023) | C31: Soil quality assessment based on MCDA-GIS hybrid approach for sustainable hazelnut farming under humid ecosystem environment | D31: Soil quality assessment for hazelnut farming | E31: NA (GIS) | G31: 1 | H31: 10.1007/s12210-023-01179-9 | I31: {=XLOOKUP(C31, 'raw data'!A:A, 'raw data'!C:C, "Not found")} | J31: Turkey | K31: {=XLOOKUP(C31, 'title&tool'!A:A, 'title&tool'!B:B, "Not found")} | L31: Non-SEA → review for removal | M31: 2.3 Robotics | N31: Yes
A32: {=XLOOKUP(C32, 'raw data'!A:A, 'raw data'!D:D, "Not found")} | B32: Bellam et al. (2023) | C32: Mapping Shrimp Pond Dynamics: A Spatiotemporal Study Using Remote Sensing Data and Machine Learning | D32: Shrimp pond mapping & monitoring | E32: Satellite | G32: 1 | H32: 10.3390/agriengineering5030089 | I32: {=XLOOKUP(C32, 'raw data'!A:A, 'raw data'!C:C, "Not found")} | J32: Vietnam | K32: {=XLOOKUP(C32, 'title&tool'!A:A, 'title&tool'!B:B, "Not found")} | L32: SEA | M32: 2.1 Remote Sensing, 2.4 AI Models | N32: No
A33: {=XLOOKUP(C33, 'raw data'!A:A, 'raw data'!D:D, "Not found")} | B33: Belton et al. (2025) | C33: Geospatial analysis enables combined poultry-fish farm monitoring in the fragile state of Myanmar | D33: Poultry-fish farm monitoring | E33: Satellite | G33: 1 | H33: 10.1038/s43016-025-01192-1 | I33: {=XLOOKUP(C33, 'raw data'!A:A, 'raw data'!C:C, "Not found")} | J33: Myanmar | K33: {=XLOOKUP(C33, 'title&tool'!A:A, 'title&tool'!B:B, "Not found")} | L33: SEA | M33: 2.1 Remote Sensing; 2.3 Robotics | N33: No
A34: {=XLOOKUP(C34, 'raw data'!A:A, 'raw data'!D:D, "Not found")} | B34: Berchoux et al. (2023) | C34: Effect of planning policies on land use dynamics and livelihood opportunities under global environmental change: Evidence from the Mekong Delta | D34: Land use dynamics & livelihood opportunities | E34: Satellite | G34: 0 | H34: 10.1016/j.landusepol.2023.106752 | I34: {=XLOOKUP(C34, 'raw data'!A:A, 'raw data'!C:C, "Not found")} | J34: Vietnam | K34: {=XLOOKUP(C34, 'title&tool'!A:A, 'title&tool'!B:B, "Not found")} | L34: SEA | M34: 2.1 Remote Sensing | N34: No
A35: {=XLOOKUP(C35, 'raw data'!A:A, 'raw data'!D:D, "Not found")} | B35: Bethuel et al. (2025) | C35: Applying the Dempster-Shafer Fusion Theory to Combine Independent Land-Use Maps: A Case Study on the Mapping of Oil Palm Plantations in Sumatra, Indonesia | D35: Oil palm plantation mapping | E35: NA (Data Fusion of existing maps) | G35: 1 | H35: 10.3390/rs17020234 | I35: {=XLOOKUP(C35, 'raw data'!A:A, 'raw data'!C:C, "Not found")} | J35: Indonesia | K35: {=XLOOKUP(C35, 'title&tool'!A:A, 'title&tool'!B:B, "Not found")} | L35: SEA | M35: General | N35: Yes
A36: {=XLOOKUP(C36, 'raw data'!A:A, 'raw data'!D:D, "Not found")} | B36: Bethuel et al. (2024) | C36: DISCRIMINATING INDUSTRIAL AND SMALLHOLDER OIL PALM PLANTATIONS IN INDONESIA USING SENTINEL-1 TEXTURAL FEATURES | D36: Discriminating industrial and smallholder oil palm | E36: Satellite | G36: 1 | H36: 10.1109/IGARSS53475.2024.10641360 | I36: {=XLOOKUP(C36, 'raw data'!A:A, 'raw data'!C:C, "Not found")} | J36: Indonesia | K36: {=XLOOKUP(C36, 'title&tool'!A:A, 'title&tool'!B:B, "Not found")} | L36: SEA | M36: 2.1 Remote Sensing; 4/5 Practical/Adoption | N36: Yes
A37: {=XLOOKUP(C37, 'raw data'!A:A, 'raw data'!D:D, "Not found")} | B37: Bhandari & Xue (2025) | C37: Integrating multivariate statistical analysis and geospatial approaches for sediment contamination: a case study in the great Chao Phraya River network, Thailand | D37: Sediment contamination analysis | E37: NA (Geospatial approaches) | G37: 0 | H37: 10.1007/s11368-025-04051-5 | I37: {=XLOOKUP(C37, 'raw data'!A:A, 'raw data'!C:C, "Not found")} | J37: Thailand | K37: {=XLOOKUP(C37, 'title&tool'!A:A, 'title&tool'!B:B, "Not found")} | L37: SEA | M37: General | N37: No
A38: {=XLOOKUP(C38, 'raw data'!A:A, 'raw data'!D:D, "Not found")} | B38: Bhumiphan et al. (2023) | C38: Estimation of Rubber Yield Using Sentinel-2 Satellite Data | D38: Rubber yield estimation | E38: Satellite | G38: 1 | H38: 10.3390/su15097223 | I38: {=XLOOKUP(C38, 'raw data'!A:A, 'raw data'!C:C, "Not found")} | J38: Thailand | K38: {=XLOOKUP(C38, 'title&tool'!A:A, 'title&tool'!B:B, "Not found")} | L38: SEA | M38: 2.1 Remote Sensing | N38: Yes
A39: {=XLOOKUP(C39, 'raw data'!A:A, 'raw data'!D:D, "Not found")} | B39: Binh et al. (2024) | C39: Application of GIS in land unit mapping and evaluation of land suitability for agriculture in Uong Bi district - Quang Ninh province | D39: Land unit mapping & suitability for agriculture | E39: NA (GIS) | G39: 1 | H39: 10.1088/1755-1315/1345/1/012017 | I39: {=XLOOKUP(C39, 'raw data'!A:A, 'raw data'!C:C, "Not found")} | J39: Vietnam | K39: {=XLOOKUP(C39, 'title&tool'!A:A, 'title&tool'!B:B, "Not found")} | L39: SEA | M39: General | N39: No
A40: {=XLOOKUP(C40, 'raw data'!A:A, 'raw data'!D:D, "Not found")} | B40: Blanton et al. (2024) | C40: Ecotourism and mangrove conservation in Southeast Asia: Current trends and perspectives | D40: Ecotourism & mangrove conservation | E40: NA (Literature Review) | H40: 10.1016/j.jenvman.2024.121529 | I40: {=XLOOKUP(C40, 'raw data'!A:A, 'raw data'!C:C, "Not found")} | J40: Southeast Asia | K40: {=XLOOKUP(C40, 'title&tool'!A:A, 'title&tool'!B:B, "Not found")} | L40: SEA | M40: Intro/Background | N40: No
...

Sheet raw data
A1: Article Title | B1: Source Title | C1: Abstract | D1: Authors
A2: Mapping smallholder plantation as a key to sustainable oil palm: A deep learning approach to high-resolution satellite imagery | B2: APPLIED GEOGRAPHY | C2: The adverse impacts of oil palm plantations on socio-ecological conditions in Indonesia are a prominent issue. While farming improvement in large-scale plantations has shown good progress, accelerated expansion coupled with low productivity of smallholder plantations has raised concerns. Smallholder plantations are rarely moni-tored, as they are small, scattered, fragmented, often located in remote areas, with irregular shapes, susceptible to rapid change, and commonly mixed with other commodities. Accordingly, the present study aimed to (1) develop a new model for mapping smallholder oil palms, (2) describe the spatial distribution of smallholder oil palms, and (3) identify their potential impact on the environment. An object detection model based on a deep-learning approach was applied to high-resolution satellite imagery from Google Earth, Pleiades, and GeoEye to detect individual oil palm trees. The results showed that the derived model is highly accurate and can suc-cessfully map smallholder plantations. Village-level maps showed that the spatial distribution of smallholder oil palms was strongly related to local socio-ecological dynamics, whereas regency-level maps showed that small-holder oil palms have largely encroached on conservation zones and forested areas. These findings highlight the urgency of smallholder oil palm spatial data for reaching sustainable global palm oil industries. | D2: Pribadi, DO; Rustiadi, E; Iman, LS; Nurdin, M; Saad, A; Pravitasari, AE; Mulya, SP; Ermyanyla, M
A3: Automatic detection and counting of oil palm trees using remote sensing and object-based deep learning | B3: REMOTE SENSING APPLICATIONS-SOCIETY AND ENVIRONMENT | C3: Palm oil is one of the world's highest vegetable oil producers. Providing accurate oil palm planta-tion statistics is essential to supporting effective and efficient decision-making, especially since the oil palm industry has a strategic role in achieving several Sustainable Development Goals (SDGs). The existing conventional data collection has been focusing on field survey methods which require considerable human resources and costs, long collection and processing times, and have difficulty in reaching remote areas. Remote sensing with satellite imagery and Unmanned Aerial Vehicles (UAV) can be an alternative due to its advantages which include a more efficient workforce, shorter update times, comprehensive area coverage, and the ability to reach remote locations. In this study, we propose the utilization of Microsoft Bing Maps Very High Resolution (VHR) satellite imagery and UAV with image processing threshold and object-based deep learn-ing methods to detect and count the number of oil palm trees. Experimental results in a case study in Rokan Hulu Regency, Riau, Indonesia show that the object-based deep learning model of the You Only Look Once (YOLO) architecture achieves excellent performance with an F1-Score of up to 91.05%. This model is superior to the widely adopted baseline model of the image processing threshold, which only reached an F1-Score of 40.59%. Our findings suggest the use of very high resolution images with object-based deep learning is promising for automatic detection and counting of oil palm trees to support the accurate and sustainable agricultural monitoring. | D3: Putra, YC; Wijayanto, AW
A4: Mapping predicted dung beetle diversity in the lowland tropical forests of Borneo by utilizing indices derived from a satellite image | B4: JOURNAL OF FOREST RESEARCH | C4: In tropical regions, assessing biodiversity across expansive areas through direct data collection presents significant challenges. The advancement of remote sensing techniques for mapping predicted biodiversity offers a viable solution. To map predicted dung beetle diversity and its associated ecological functions using satellite images, we selected optimal multivariate regression models to predict overall species richness and abundance, forest species richness and abundance, biomass (logarithmic dry weight) associating ecological functions of the beetle, Simpson's diversity index (1/D), and forest community integrity (measured as the score on axis 1 of nonmetric multidimensional scaling ordination analysis), utilizing the Akaike information criterion (AIC). The explanatory variables were extracted from a SPOT-5 satellite image utilizing varying grid cell configurations up to 290 m2. The objective variables consisted of dung beetle collection data from intact, burnt, or artificially degraded natural forests; plantation forests; and grasslands within a 20 x 20 km area near Balikpapan, Indonesia. When the predicted and observed values were compared, the coefficients of determination of the linear model exhibited marked significance, with all relations having an R2 exceeding 0.25. Mapping these predicted values revealed that the areas with high values generally coincided with the large intact natural forests and the remnants surrounding burnt areas, except for overall and forest species abundances, which displayed higher values along the burnt ridges surrounding the intact natural forests. These findings demonstrate that the mapping of predicted dung beetle diversity and its associated ecological functions within tropical regions can be effectively achieved through the use of satellite images. | D4: Ueda, A; Ito, H; Dwibadra, D; Kahono, S; Syah, TH; Takahashi, M
A5: Free satellite image data application for monitoring land use cover changes in the kon ha nung plateau, vietnam | B5: HELIYON | C5: Remote sensing imagery is the most suitable tool for monitoring, managing, and evaluating land -use overlay fluctuations, especially forest cover for large areas. Free-and medium-resolution satellite imagery is a useful tool that allows scientific researchers and management organiza-tions to monitor forest development in developing countries, such as Vietnam. In this study, we used SPOT 4 and Planet remote sensing data to assess land-use status fluctuations in the Kon Ha Nung Plateau area, Vietnam, between 2000 and 2021 (the overall accuracy was 90.52%, Kappa value = 0.89). The results showed that from 2000 to 2010, the rate of natural forest loss in this area was 0.32%/year, of which, more than 6500 ha were converted to other uses. Between 2010 and 2021, the rate of natural forest loss gradually decreased (0.09%/year) instead of fluctuating between different types of land use. The area of forests, perennial crop land, and annual crop land tended to increase from 2000 to 2010; however, from 2010 to 2021, the area of plantation forests decreased markedly, while the area of perennial crop land and annual crop land continued to expand. The analysis of the policies on forest management, exploitation, and protection was applied locally, to explain the causes of the change in spatiotemporal aspects of the types of land -use cover in the Kon Ha Nung Plateau. Restoring forest areas during 2010-2021 initially improved effectiveness in forest management and protection. Furthermore, the results provide a better understanding of the current position and role of the government apparatus, cadres, and ethnic minorities in socioeconomic development associated with forest protection and develop-ment on the Kon Ha Nung Plateau. The results of this study can help managers monitor annual forest-cover fluctuations based on free remote sensing imagery to reduce both the cost of man-agement and surveying, yielding relatively accurate results. | D5: Dinh, DB; Ngo, DT; Nguyen, HD; Nguyen, HHV; Dang, NT
A6: Single Oil Palm Tree Detection and Its Potential Expansion in Honduras | B6: IEEE TRANSACTIONS ON GEOSCIENCE AND REMOTE SENSING | C6: Honduras is among the ten largest palm oil producers in the world. Accurately detecting the current plantation status and oil palm distribution is crucial to optimize the planting layout. However, current information on single oil palm trees in Honduras is scarce. Here, we used submeter-resolution RGB satellite images in 2022 to detect the spatial distribution and single oil palm tree in Honduras with the four-direction gradient difference (FGD), single-tree feature extraction, and double-ring detection methods. In the accuracy validation zones, the recall, precision, and F1-score metrics for the spatial distribution of oil palm were 86.50%, 86.57%, and 86.53%, respectively; counting accuracy for single oil palm trees was 86.75%; and localization accuracy was approximately 6 m. We estimated 0.25 million hectares (ha) of oil palm plantation area in Honduras, corresponding to 28.27 million trees and an average density of 113 trees/ha. Furthermore, we categorized planted land into highly or moderately suitable zones for future expansion. Among the 0.25 million ha of potentially available land, the highly and moderately suitable zones represented 10 501 and 242 120 ha, respectively, with the potential to carry approximately 28.55 million oil palms. For future oil palm expansion, priority should be given to highly suitable zones. This study not only characterized the distribution and single oil palm properties in Honduras but also suggested potentially suitable zones for future plantation expansion, thereby providing important methodological references and data support to assess the impact of oil palm planting on the ecological environment and socioeconomic aspects at the country scale. | D6: Zhang, H; Cui, YP; Yu, L; Andino, REC; Zhang, S; Cui, KL; Zhao, TW; Liang, H
A7: Utilizing a fusion of remote sensing data and machine learning models to forecast flood risks to agriculture in Hanoi City, Vietnam | B7: LETTERS IN SPATIAL AND RESOURCE SCIENCES | C7: Floods represent a substantial and consequential from of natural disasters within Hanoi City. To minimize the detrimental effects on agriculture, an all-encompassing decision support instrument is necessary for flood management and alert systems. The primary aim of the current study is to delineate flood susceptible regions by employing SPOT satellite imagery and a hybrid Principal Component Analysis-Support Vector Machine (PCA-SVM) model, thereby gauging the influence of floods on land utilization for agricultural purposes in Hanoi City. The prediction results demonstrate a high model performance with R2test = 0.904, and AUC = 0.921. Areas classified as exhibiting high to very high flood susceptible encompass 55.882% of the overall expanse, while those classified as having low and very low flood risk account for 10.357% and 6.278% respectively. The amalgamation of satellite imagery and the PCA-SVM model in the formulation of flood susceptible zoning maps confers valuable insights to bolster flood prevention endeavors. The current research findings will make a substantial contribution to the strategic planning and preservation of food security for the nation. | D7: Do, ANT
A8: Assessment of forest cover and forest loss using satellite images in Thua Thien Hue province, Vietnam | B8: AUC GEOGRAPHICA | C8: Deforestation in the tropics continues inexorably with severe implications for biodiversity conservation, climate regulation and ecosystem services. This study investigated variation in forest cover in Thua Thien Hue province, Vietnam, using the Landsat Thematic Mapper and Operational Land Imager satellite images over the period 1989-2021. Imageries were classified using the maximum likelihood classification technique for the years 1989, 2006, and 2021 and were evaluated for accuracy using the kappa coefficient for each year. Furthermore, forest cover losses and gains were evaluated using the Normalized Difference Vegetation Index and Soil Adjusted Vegetation Index, which were compared with the output of the supervised classification. Results showed that the forest cover of Thua Thien Hue province has drastically declined over the years. The forest cover, which was estimated at 68.88% (3461.46 km2) of the total land area in 1989, increased to 69.04% (3469.51 km2) in 2006 and subsequently decreased to 57.55% (2891.81 km2) in 2021. Severely reduced forest cover is often associated with the expansion of agriculture on the forest edge; other contributing factors include logging, illegal production land, and forest fires. Overall, our results show the necessity of forest management, rational land-use planning policy, and increased community awareness of conservation and sustainable development of forest resources in the study area in the future. | D8: Thien, BB; Phuong, VT; Komolafe, AA
A9: Mapping and Assessment of Burned Areas in Palawan, Philippines using SAR Burned and Vegetation Indices | B9: EIGHTH GEOINFORMATION SCIENCE SYMPOSIUM 2023: GEOINFORMATION SCIENCE FOR SUSTAINABLE PLANET | C9: Palawan is considered the last frontier of the Philippines; in light of this, the province receives special attention from the national and international community. Despite this, there are still numerous issues that need to be addressed, including illegal burning activities. Based on reports and satellite image analyses, slash-and-burn (kaingin) farming is pervasive in Palawan. Burned areas are easily detected from optical satellite images using the Normalized Burn Ratio (NBR) or similar indices. However, the usefulness of optical imagery is severely limited by persistent cloud cover, especially in upland areas where kaingin is commonly practiced. This study focuses on the utilization of Sentinel-1 SAR data in monitoring the burned areas due to its ability to penetrate clouds, smoke, and haze. Radar burn and vegetation indices such as Radar Burn Difference (RBD), Radar Burn Ratio (RBR), Radar Vegetation Index (RVI), and Radar Forest Degradation Index (RFDI) were used to detect the burned areas. These were then cross-validated with the NBR layer. RBD index yielded better results compared to other radar burn and vegetation indices in mapping the burned areas. Additionally, the RBD using the VH polarization band provided detailed delineation of burned areas than that using the VV polarization band. In the operational monitoring of burned areas, the synergistic use of burned indices from optical and SAR images is recommended. | D9: Vergara, DCDM; Canlas, CPI; Blanco, AC
A10: Bare Land Referenced Algorithm from Hyper-Temporal Data (BRAH) for Land Use and Land Cover Age Estimation | B10: LAND | C10: Determining the age of land use and land cover (LULC) using satellite imagery has long been one of the challenging tasks in remote sensing research. Accurately determining age, especially crop age, is essential for plot management, biomass calculations, and carbon sequestration. This research proposes a method for determining the age of LULC using hyper-temporal satellite data. The method is based on the assumption that the starting point for the age count is when the latest bare land status disappears at any location. To create a geospatial layer (referred to as the BR layer) that can be used to determine the age of any land cover at a specific location, we conditionally stacked such statuses obtained from the analysis of numerous satellite imagery data. The algorithm was tested at two study sites in Thailand, where rubber plantations dominated land use. The study revealed that all the rubber ages determined using BRAH fell accurately within the range of the local government survey data. The manuscript provides a straightforward explanation of the algorithm, including the pseudocode, accuracy assessment, implementations, robustness, and limitations. | D10: Boonprong, S; Khantachawana, A
A11: Automatic deforestation driver attribution using deep learning on satellite imagery | B11: GLOBAL ENVIRONMENTAL CHANGE-HUMAN AND POLICY DIMENSIONS | C11: Deforestation is a leading contributor to greenhouse gas emissions globally. Understanding the direct drivers of forest loss is essential for developing targeted forest conservation and management policies. However, this data is hard to collect at scale due to the complexity of forest loss drivers and expertise required for accurately identifying them. To address this challenge, we developed a deep learning model called ForestNet which uses publicly available satellite imagery to automatically classify the drivers of primary forest loss. We validated ForestNet on a test set of expert-annotated forest loss events and showed that ForestNet achieved high performance across four major driver classes. We used ForestNet to identify these drivers on over 2 million forest loss events in Indonesia between 2012 and 2019, with significant improvement in spatial and temporal resolution over previously available data. We found that plantations and smallholder agriculture were the primary direct drivers of deforestation in Indonesia during this period, accounting for 64 % of total forest loss. Deforestation has decreased steadily since 2012 after increasing steadily from 2001 to 2009 and peaking from 2009 to 2012, trends that we found are primarily due to changes in plantation-driven deforestation. Our approach can serve as a general framework for scalably attributing deforestation to specific drivers and can be extended to other regions of interest, providing a flexible and cost-effective way for countries to regularly monitor, understand, and address their unique and dynamic drivers of deforestation. | D11: Ramachandran, N; Irvin, J; Sheng, H; Johnson-Yu, S; Story, K; Rustowicz, R; Ng, AY; Austin, K
A12: Bayesian merging of numerical modeling and remote sensing for saltwater intrusion quantification in the Vietnamese Mekong Delta | B12: ENVIRONMENTAL MONITORING AND ASSESSMENT | C12: Saltwater intrusion has become one of the most concerning issues in the Vietnamese Mekong Delta (VMD) due to its increasing impacts on agriculture and food security of Vietnam. Reliable estimation of salinity plays a crucial role to mitigate the impacts of saltwater intrusion. This study developed a hybrid technique that merges satellite imagery with numerical simulations to improve the estimation of salinity in the VMD. The salinity derived from Landsat images and by numerical simulations was fused using the Bayesian inference technique. The results indicate that our technique significantly reduces the uncertainties and improves the accuracy of salinity estimates. The Nash-Sutcliffe coefficient is 0.74, which is much higher than that of numerical simulation (0.63) and Landsat estimation (0.6). The correlation coefficient between the ensemble and measured salinity is relatively high (0.88). The variance of the ensemble salinity errors (5.0 ppt2) is lower than that of Landsat estimation (10.4 ppt2) and numerical simulations (9.6 ppt2). The proposed approach shows a great potential to combine multiple data sources of a variable of interest to improve its accuracy and reliability wherever these data are available. | D12: Tran, AP; Son, DH; Duc, NA; Chien, PV; Nguyen, TT; Tran, MC; Nguyen, NA; Le, PVV; Pham, HV
... A156: Investigating Farmers' Perceptions of Drone Technology in Thailand: Exploring Expectations, Product Quality, Perceived Value, and Adoption in Agriculture | B156: AGRICULTURE-BASEL | C156: This study examines farmers' perceptions of drone technology in agriculture, highlighting its growing importance in modern farming. Despite the potential benefits of drones, there remains a research gap in understanding how factors like expectations, product quality, and perceived value influence adoption. This research seeks to fill that gap through a survey of 410 farmers in Thailand who have prior drone usage experience. The methodology employed a quantitative approach using structured questionnaires, with data analyzed through Structural Equation Modeling (SEM). The results indicate that expectations, mediated by perceived product quality and value, significantly influence farmers' attitudes toward drone technology. Product quality-particularly in terms of precision, durability, and ease of use-emerged as a key factor in shaping trust and adoption. Economic, social, and personal perceptions were also found to drive perceived value. The study concludes that aligning drone features with farmer expectations can increase perceived value, facilitating wider adoption. Policymakers and service providers are encouraged to focus on enhancing product functionality and offering targeted educational programs to build confidence among farmers. This research contributes to a deeper understanding of the socioeconomic factors influencing agricultural innovation and offers practical recommendations for promoting sustainable technological adoption in the sector. | D156: Suvittawat, A
A157: Use of GIS and machine learning to pre- dict disease in shrimp farmed on the east coast of the Mekong Delta, Vietnam | B157: NIPPON SUISAN GAKKAISHI | D157: Khiem, NM; Oanh, DTH; Hai, TN; Ut, VN
A158: Use of GIS and machine learning to predict disease in shrimp farmed on the east coast of the Mekong Delta, Vietnam (vol 88, pg 1, 2022) | B158: FISHERIES SCIENCE | D158: Khiem, NM; Takahashi, Y; Yasuma, H; Oanh, DTH; Hai, TN; Ut, VN; Kimura, N
A159: Uncovering Dynamics of Global Mangrove Gains and Losses | B159: REMOTE SENSING | C159: Supporting successful global mangrove conservation and policy requires accurate identification of anthropogenic and biophysical drivers of mangrove extent, yet such studies are scarce. We apply a hybrid methodology, combining existing remote sensing mangrove maps with local expert knowledge of vegetation and land use dynamics. We conducted stratified random sampling in eight subregions, and local experts visually interpreted over 20,900 plots using high-resolution imagery in Collect Earth Online. Similar to previous estimates, we found 147,771 km(2) (& PLUSMN;1.4%) of mangroves globally in 2020 and that rates of mangrove loss have decreased from 2000-2010 to 2010-2020, largely driven by South and Southeast Asia. Anthropogenic drivers of loss have shifted across subregions, with oil palm cultivation emerging in South and Southeast Asia and aquaculture in South America and Western and Central Africa, highlighting the need for ongoing monitoring and adaptable conservation efforts. Natural expansion outpaced natural retraction in both periods. This is the first global study uncovering land use drivers of mangrove decline and recovery, only made possible by collaboration with local experts. Key breakthroughs include successfully discerning spectrally similar anthropogenic from biophysical drivers, such as aquaculture from natural retraction, and creating data collection approaches that streamline visual interpretation efforts. | D159: Contessa, V; Dyson, K; Mulas, PPV; Kindgard, A; Liu, TC; Saah, D; Tenneson, K; Pekkarinen, A
A160: Multi-spectral remote sensing and GIS-based analysis for decadal land use land cover changes and future prediction using random forest tree and artificial neural network | B160: ADVANCES IN SPACE RESEARCH | C160: The integration of multi-spectral remote sensing and GIS-based analysis is significant for studying land cover changes, providing valuable insights for informed land management and sustainable development. The present study aims to examine land use land cover (LULC) changes of three decades from 1991 to 2021 and predict the future LULC change in Binh Duong province, Vietnam to explore a future research direction on land use change and associated challenges in the study region. Multi-spectral remote sensing data and random forest tree (RFT) were utilized to generate LULC maps. Areal statistics and annual change rate were considered to analyze the categorical land use change detection. Statistical measures such as user's accuracy, producer's accuracy, kappa coefficient, and confusion matrix were employed to assess the accuracy of LULC classification. To predict future LULC and simulate the spatio-temporal change, we considered previous year LULC maps, independent spatial variables and a combined artificial neural network (ANN) multi-layer perceptron approach. The analysis revealed that there was a huge transition from agricultural lands to residential land with industry and commerce which resulting an expansion of impervious lands and a rapid decline of agricultural land as well as of scrub land and barren lands, and a changeability of forest and plantation, croplands, and waterbodies. Our study revealed that the impervious land has expanded 10 times within 30 years and will increase in the future. (c) 2024 Published by Elsevier B.V. on behalf of COSPAR. | D160: Pham, QB; Ali, SA; Parvin, F; On, VV; Sidek, LM; Durin, B; Cetl, V; Samanovic, S; Minh, NN
A161: Policy Evaluation and Monitoring of Agricultural Expansion in Forests in Myanmar: An Integrated Approach of Remote Sensing Techniques and Social Surveys | B161: LAND | C161: Agricultural expansion is the main driver of deforestation in Myanmar. We analyzed the effectiveness of a national policy intervention on agricultural encroachment in state forests in Taungoo District in Myanmar from 2010 to 2020. The policy aims to stop agricultural encroachment and reforest encroached areas through farmers' participation in an agroforestry community forestry. We applied an integrated approach that involved a land cover change analysis together with a household survey about encroachment behavior. The remote sensing analysis for the years 2010, 2015 and 2020 showed the land cover change pattern and an increase in agricultural encroachment from 9.5% to 18.5%, while forests declined from 62.8% to 51.9%. The survey showed that most farmers (91%) believed that the policy intervention did not lead to a change in their encroachment behavior or farm size. The main reasons that incentivized encroachment were stated to be livelihood needs, immigration due to marriage and increased accessibility due to road construction. The main reason for reducing encroachment was plantation establishment, leading to a loss of land for encroaching farmers. In conclusion, the integrated approach showed that the policy intervention did not decrease encroachment, whereas other factors influenced encroachment behavior. We recommend solving interministerial conflicts of interest related to encroachment in Myanmar and using an integrated approach for future studies. | D161: San, SM; Kumar, N; Biber-Freudenberger, L; Schmitt, CB
A162: Are there suitable global datasets for monitoring of land use and land cover in the tropics? Evidences from mainland Southeast Asia | B162: GLOBAL AND PLANETARY CHANGE | C162: The freely available Land Use and Land Cover (LULC) datasets are effective tool for tracking land surface changes, ecosystem dynamics, and carbon cycle. However, the issue of the uncertainly, applicability, and limitations of LULC data products is always a challenge and varies distinctively worldwide, especially in the tropics where forest loss is rapid. Eight of the most widely used LULC datasets, here, including 500-m MCD12Q1, 300-m ESA CCI-LC, 30-m GlobelLand30, 30-m GLC_FCS30, 30-m FROM-GLC, 10-m World Cover, 10-m Esri Land Cover, and 10-m FROM-GLC10, were statistically compared and evaluated the consistency and reliability in Mainland Southeast Asia (MSEA). The results revealed that the FROM-GLC10, World Cover, and GLC_FCS30 have higher accuracy than the other five datasets, with overall accuracy ranging from 90.8 to 92.2%, while FROM-GLC had the lowest accuracy of 77.7%. GlobeLand30, FROM-GLC, and FROM-GLC10 were the most similar with a correlation coefficient of 0.999 compared to only 0.882 for ESA CCI-LC and World Cover. Eight LULC-based forests (52.2%-70.4%) and cropland (21.6%-43.9%) are the predominant LULCs in MSEA, with the ESA CCI-LC having the largest estimated area (844,800 km2, 43.9%) of cropland, which also results in it having the smallest area (52.2%) of forest. Compared to other datasets, Esri Land Cover had the most extensive distribution of built-up land (4.9%), while World Cover had larger areas of grassland cover (9.8%). In particular, the spatial patterns of cropland and forest are highly consistent, but there are significant local differences, e.g., in western Myanmar and southern Vietnam. The MCD12Q1, ESA CCI-LC, and GLC_FCS30 showed consistent overall trends in forest change across the five countries of MSEA over the past two decades, while GlobelLand30 produced different results. Our cross-comparison and evaluation based on eight global LULC datasets in MSEA highlighted the consistency and differences, which will help to select the suitable dataset for specific needs (e.g., regional ecosystem response to forest loss) in the future. | D162: Zhai, JH; Xiao, CW; Feng, ZM; Liu, Y
A163: Implementation of Slicing Aided Hyper Inference (SAHI) in YOLOv8 to Counting Oil Palm Trees Using High-Resolution Aerial Imagery Data | B163: INTERNATIONAL JOURNAL OF ADVANCED COMPUTER SCIENCE AND APPLICATIONS | C163: Palm oil is a commodity that contributes significantly to Indonesia's national economic growth, with a total plantation area of 116,000 hectares. By 2023, Indonesia is projected to produce approximately 47 million metric tons of palm oil. One of the major challenges in the manual counting of oil palm trees in a large area of a plantation is the labour-intensive, timeconsuming, costly, and dangerous nature of the work in the field. The use of aerial imagery allows for the mapping of large areas with comprehensive data coverage. This study proposes a method of mapping oil palm plantations for the counting of oil palm trees using high-resolution aerial images taken with drones. Furthermore, the use of artificial intelligence (AI) methods and deep learning (DL) with the You Only Look Once (YOLO) model for object detection has demonstrated good accuracy in previous studies. This research will utilize the YOLOv8m object detection model and the slicing method, namely Slicing Hyper Aided Hyper Inference (SAHI), which is anticipated to enhance the precision of object detection models on high-resolution aerial imagery. The study concluded that the use of the SAHI slicing method can significantly enhance the accuracy of the model, as evidenced by a Mean Absolute Percentage Error (MAPE) value of 0.01758 on aerial imagery equivalent to 73.2 hectares, with a detection time of 5 minutes and 45 seconds. | D163: Zhorif, NN; Anandyto, RK; Rusyadi, AU; Irwansyah, E
A164: Agricultural land suitability analysis in Manipur, India using GIS and AHP | B164: AUC GEOGRAPHICA | C164: This article aims to identify potential sites for agricultural use in the state of Manipur of north east India by employing the analytic hierarchy process in a geographic information system environment in conjunction with the use of remote sensing and soil data. Within the analytic hierarchy process, each terrain variable underwent a pairwise comparison and criteria weights were assigned according to their relative importance. Eight variables were selected and used in land suitability analysis for agriculture. It was found that Manipur had 57% (12,660 km2) of its total geographical area suitable for agriculture. However, 8126 km2 (37%) and 1374 km2 (6%) of the total geographical area was currently and permanently unsuitable land respectively. The distribution of suitable land varied greatly, with highly, moderately and marginally suitable land covering only 8%, 16% and 33% respectively of the total geographical area. The highly suitable agricultural land is predominantly concentrated in the Imphal valley (70%), though 90% of moderately suitable and 96% of marginally suitable land also exist in the hills. The hilly areas constitute 96% and 97% respectively of currently unsuitable and permanently unsuitable land in the state. Suitable land comprises of land with low to medium altitude, gentle to moderate slopes, soil of fine or acceptable quality, and with minimal flood risk. Unsuitable lands tend to be diametrically opposite to these attributes with steep hill slopes. The nature of distribution of land suitability types influences the agricultural pattern in Manipur. Agriculture in the hill areas comprises mainly of shifting cultivation on hill slopes, whereas in the valley region it is irrigated and permanent. This analysis of Manipur has a wider applicability since the shifting cultivation-irrigated agriculture combination is similar to that which exists across much of the highlands of South East Asia. | D164: Baite, L; Bhattacharjee, N; Debbarma, J; Saikia, A
A165: The Study of Extraction Soil Salinity Information from High Resolution Multispectral Remote Sensing Data, Pilot Area in DongNai Province, Vietnam | B165: ADVANCES IN RESEARCH ON WATER RESOURCES AND ENVIRONMENTAL SYSTEMS | C165: Soil salinity is one of the causes that directly affect agriculture in many countries and territories around the world. This study establishes a map of saline soils in the area of Long Thanh and Nhon Trach districts, Dong Nai province, using Sentinel-2 data taken in the dry season 2020-2021. The indicators used are Salinity Index, SI and Enhanced Vegetation Index, EVI. The electrical conductivity (EC) data collected at that time was used to build a suitable model for the study area on the basis of correlation with the used indicators. On the basis of correlation calculations of a multiple linear regression model with the determination coefficient of approximately 0.75. At the same time, the March 2021 Sentinel-2 dataset is used to map saline soils as this is when saline soils are most apparent. | D165: Chu, XH; Nguyen, MN; Dinh, ND; Le, TT; Bui, QH; Pham, TL; Tong, THA; Trinh, VT; Nguyen, VL
A166: An antimicrobial resistance gene situationer in the backyard swine industry of a Philippine City | B166: SCIENTIFIC REPORTS | C166: Antimicrobial resistance (AMR) as a result of antimicrobial overuse and misuse in agriculture is a growing concern, especially in the predominant but poorly regulated backyard or smallholder swine farms of the Philippines. A city-scale surveillance of antimicrobial resistance genes (ARGs) was conducted through selected backyard swine farms to obtain a comprehensive understanding of the AMR situation in the backyard sector of Davao City, Philippines. The ARGs encoding resistance to four antimicrobial classes (beta-lactams: blaCTX-M, blaOXA, blaSHV, blaTEM, mecA; quinolones: qnrS and qnr-A2; macrolides: ermA and ermB; tetracycline: tetM) were quantified in swine feces via real-time PCR, and point maps were generated to visualize the ARG geographic distribution. The ARGs bla-TEM, ermB, qnrS, and tetM were detected in all farms at relatively intermediate to high levels, consistently representing the four most used antimicrobial classes in Philippine farms. All the investigated ARGs were present in some local barangay units, indicating potential emergence of AMR hotspots. A 0.5 quantile regression analysis identified specific backyard farm attributes associated with ARG occurrence and diversity, which may influence the ecological spread of the ARGs. These findings provide support for evidence-based guidelines to reinforce a One Health framework for the Philippine National Action Plan to Combat AMR. | D166: Lumabao, JPD; Otero, MCB; Acaso, JT; Alviola, PA IV; Jaraula, CMB; Murao, LAE
A167: Mapping utilizable rooftop areas to meet food security goal in four high-density cities: A deep learning and GIS integrated approach | B167: SUSTAINABLE CITIES AND SOCIETY | C167: Food security is a key sustainable development goal globally, and rooftop agriculture offers a promising solution for high-density cities. However, many rooftops are occupied by uses such as photovoltaic panels or green roofs. Therefore, identifying utilizable rooftops for agriculture must exclude occupied rooftops, defined as those that are not vacant or already have other installations, a consideration often overlooked in previous studies. In this study, a deep learning and GIS integrated model was developed to more precisely identify and exclude these areas, including unusable rooftops and occupied roofs. This model was applied to four high-density cities across diverse climate regions: Singapore, Hong Kong (China), Toronto (Canada), and Amsterdam (Netherlands). The findings revealed utilizable rooftop areas of 619 hectares in Singapore, 607 hectares in Hong Kong, 1,870 hectares in Toronto, and 297 hectares in Amsterdam. Different development scenarios revealed varying food selfsufficiency levels. By accounting for vertical farming and technological advancements, the four cities could achieve food self-sufficiency levels of 34.71 %, 22.35 %, 112 %, and 74 %, respectively, by 2030. Singapore, in particular, could meet its 30 by 30 '' food security target. Additionally, converting existing green roofs into agricultural use could further increase self-sufficiency by 33.29 %, 9.89 %, 25.25 %, and 37.8 %, respectively. This study provides an accurate assessment of utilizable rooftop areas and their agricultural production potential in four high-density cities worldwide. The findings offer critical data and policy insights to support urban spatial planning and the implementation of rooftop agriculture, contributing to enhanced urban sustainability. | D167: Ma, CS; Yuan, C; Zhang, YF; Hu, HC
A168: TRANSFORMATION AND FRAGMENTATION OF WETLANDS IN MEKONG DELTA FLOODPLAINS: A CASE STUDY IN DONG THAP PROVINCE, VIETNAM | B168: COMPTES RENDUS DE L ACADEMIE BULGARE DES SCIENCES | C168: Wetlands in the Vietnam Mekong Delta (VMD) have experienced significant reduction and fragmentation since the economic reforms of 1986. This study analyzes land use/land cover (LULC) changes impacting wetland cover between 1990 and 2022 using Landsat imagery within the VMD floodplain, with a particular focus on Dong Thap Province. Landscape metrics were employed to quantify wetland loss and fragmentation. Results indicate that by 2022, approximately 80% of wetlands had been converted to other LULC types, predominantly for rice cultivation. Analysis of landscape metrics, including the number of patches, patch area, core area, and edge characteristics, reveals increased fragmentation, with smaller and more isolated patches replacing larger, contiguous wetlands over the past three decades. Key drivers of this fragmentation include population growth, land reclamation, agricultural expansion, and shifts in farming systems. Given the escalating impacts of climate change, these findings provide essential insights for land use planning and the development of wetland conservation strategies in the Dong Thap Province, the VMD. | D168: Nguyen, H; Dinh, TT; Phan-Van, P; Nguyen-Quoc, H
